<mujoco model="x2">
  <compiler angle="radian" meshdir="./meshes/"/>
  <default>
    <joint damping="0.1" armature="0.01" frictionloss="0.1"/>
  </default>

  <asset>
    <texture type="skybox" builtin="gradient" width="128" height="128" rgb1="0.4 0.6 0.8" rgb2="0 0 0"/>
    <texture name="plane" type="2d" builtin="checker" rgb1="0.2 0.2 0.2" rgb2="0.3 0.3 0.3" width="512"
              height="512"/>
    <material name="plane" reflectance="0.0" texture="plane" texrepeat="1 1" texuniform="true"/>
    <material name="collision" rgba="0.1 0.5 0.9 0"/>
    <mesh name="pelvis_link" file="pelvis_link.STL"/>
    <mesh name="L_hip_yaw_link" file="L_hip_yaw_link.STL"/>
    <mesh name="L_hip_roll_link" file="L_hip_roll_link.STL"/>
    <mesh name="L_hip_pitch_link" file="L_hip_pitch_link.STL"/>
    <mesh name="L_knee_pitch_link" file="L_knee_pitch_link.STL"/>
    <mesh name="L_ankle_pitch_link" file="L_ankle_pitch_link.STL"/>
    <mesh name="R_hip_yaw_link" file="R_hip_yaw_link.STL"/>
    <mesh name="R_hip_roll_link" file="R_hip_roll_link.STL"/>
    <mesh name="R_hip_pitch_link" file="R_hip_pitch_link.STL"/>
    <mesh name="R_knee_pitch_link" file="R_knee_pitch_link.STL"/>
    <mesh name="R_ankle_pitch_link" file="R_ankle_pitch_link.STL"/>
    <mesh name="waist_yaw_link" file="waist_yaw_link.STL"/>
    <mesh name="torso_link" file="torso_link.STL"/>
    <mesh name="logo_link" file="logo_link.STL"/>
    <mesh name="head_link" file="head_link.STL"/>
    <mesh name="L_shoulder_pitch_link" file="L_shoulder_pitch_link.STL"/>
    <mesh name="L_shoulder_roll_link" file="L_shoulder_roll_link.STL"/>
    <mesh name="L_shoulder_yaw_link" file="L_shoulder_yaw_link.STL"/>
    <mesh name="L_elbow_pitch_link" file="L_elbow_pitch_link.STL"/>
    <mesh name="R_shoulder_pitch_link" file="R_shoulder_pitch_link.STL"/>
    <mesh name="R_shoulder_roll_link" file="R_shoulder_roll_link.STL"/>
    <mesh name="R_shoulder_yaw_link" file="R_shoulder_yaw_link.STL"/>
    <mesh name="R_elbow_pitch_link" file="R_elbow_pitch_link.STL"/>
  </asset>

  <worldbody>
    <geom name="floor" pos="0.001 0 0" size="100 10 .125" type="plane" material="plane" condim="3"
          conaffinity="15" friction="0.6 0.6 0.001"/>
    <light mode="trackcom" pos="0 0 5" dir="0 0 -1"/>
    <light directional="true" pos="0 0 3" dir="0 0 -1" diffuse="0.2 0.2 0.2" specular="0 0 0"/>
    <body name="pelvis_link" pos="0 0 0.91">>
      <inertial pos="-0.003423 9.09152e-08 0.307997" quat="0.999796 -8.3433e-08 0.0201933 -4.13088e-06" mass="15.9092" diaginertia="0.395894 0.38141 0.0882848"/>
      <joint name="pelvis_link" type="free" limited="false" actuatorfrclimited="false"/>
      <geom type="mesh" contype="0" conaffinity="0" group="1" density="0" rgba="1 1 1 1" mesh="pelvis_link"/>
      <geom type="mesh" rgba="1 1 1 1" mesh="pelvis_link"/>
      <site name="imu" pos="0 0 0"/>
      <geom pos="0 0 0.08375" type="mesh" contype="0" conaffinity="0" group="1" density="0" rgba="1 1 1 1" mesh="waist_yaw_link"/>
<!--      <geom pos="0 0 0.08375" type="mesh" rgba="1 1 1 1" mesh="waist_yaw_link"/>-->
      <geom pos="0 0 0.1205" quat="1 0 0 0" type="mesh" contype="0" conaffinity="0" group="1" density="0" rgba="0.823529 0.823529 0.823529 1" mesh="torso_link"/>
<!--      <geom pos="0 0 0.1205" quat="1 0 0 0" type="mesh" rgba="0.823529 0.823529 0.823529 1" mesh="torso_link"/>-->
      <geom pos="0 0 0.1205" quat="1 0 0 0" type="mesh" contype="0" conaffinity="0" group="1" density="0" rgba="1 0 0 1" mesh="logo_link"/>
<!--      <geom pos="0 0 0.1205" quat="1 0 0 0" type="mesh" rgba="1 0 0 1" mesh="logo_link"/>-->
      <geom pos="0 0 0.485" quat="1 0 0 0" type="mesh" contype="0" conaffinity="0" group="1" density="0" rgba="1 1 1 1" mesh="head_link"/>
      <geom pos="0 0 0.485" quat="1 0 0 0" type="mesh" rgba="1 1 1 1" mesh="head_link"/>
      <body name="L_hip_yaw_link">
        <inertial pos="-0.0005618 0.019831 0.00885104" quat="0.416547 0.491409 -0.566922 0.513426" mass="0.841" diaginertia="0.00175713 0.00175343 0.000573392"/>
        <joint name="L_hip_yaw" pos="0 0 0" axis="0 0 1" range="-0.7854 0.7854" limited="true" actuatorfrcrange="-100 100"/>
        <geom type="mesh" contype="0" conaffinity="0" group="1" density="0" rgba="1 1 1 1" mesh="L_hip_yaw_link"/>
<!--        <geom type="mesh" rgba="1 1 1 1" mesh="L_hip_yaw_link"/>-->
        <body name="L_hip_roll_link" pos="-0.0095 0.12 0">
          <inertial pos="-0.0324725 0.00017925 -0.0726484" quat="0.655395 -0.252501 -0.247695 0.667344" mass="2.667" diaginertia="0.0108627 0.0094793 0.00603247"/>
          <joint name="L_hip_roll" pos="0 0 0" axis="1 0 0" range="-0.349 0.524" actuatorfrcrange="-100 100"/>
          <geom type="mesh" contype="0" conaffinity="0" group="1" density="0" rgba="1 1 1 1" mesh="L_hip_roll_link"/>
          <geom type="mesh" rgba="1 1 1 1" mesh="L_hip_roll_link"/>
          <body name="L_hip_pitch_link" pos="0.0085 -0.001 -0.11">
            <inertial pos="0.00382921 0 -0.185484" quat="0.706562 0.0278169 0.0278188 0.706557" mass="1.664" diaginertia="0.0148443 0.0145077 0.0030868"/>
            <joint name="L_hip_pitch" pos="0 0 0" axis="0 -1 0" range="-2.4434 2.4434" actuatorfrcrange="-100 100"/>
            <geom type="mesh" contype="0" conaffinity="0" group="1" density="0" rgba="1 1 1 1" mesh="L_hip_pitch_link"/>
            <geom type="mesh" rgba="1 1 1 1" mesh="L_hip_pitch_link"/>
            <body name="L_knee_pitch_link" pos="0 0 -0.35">
              <inertial pos="0.00140265 0 -0.15876" quat="0.706958 -0.0143173 -0.0143148 0.706965" mass="1.125" diaginertia="0.00999859 0.00987345 0.00100926"/>
              <joint name="L_knee_pitch" pos="0 0 0" axis="0 -1 0" range="2.3561 2.3561" actuatorfrcrange="-100 100"/>
              <geom type="mesh" contype="0" conaffinity="0" group="1" density="0" rgba="1 1 1 1" mesh="L_knee_pitch_link"/>
              <geom type="mesh" rgba="1 1 1 1" mesh="L_knee_pitch_link"/>
              <body name="L_ankle_pitch_link" pos="0 0 -0.35">
<!--                <inertial pos="0.0393988 -0.000237278 -0.0784143" quat="0.000325049 0.702196 0.00149391 0.711983" mass="0.556154" diaginertia="0.00260529 0.00243297 0.000325398"/>-->
                <inertial pos="0.0393988 -0.000237278 -0.0784143" quat="0 0.705556 0 0.708654" mass="0.556154" diaginertia="0.00260004 0.00215 0.000549961"/>
                <joint name="L_ankle_pitch" pos="0 0 0" axis="0 -1 0" range="-1.2217 1.2217" actuatorfrcrange="-50 50"/>
                <geom type="mesh" contype="0" conaffinity="0" group="1" density="0" rgba="1 1 1 1" mesh="L_ankle_pitch_link" euler="0 0.07 0"/>
                <geom size="0.005" pos="-0.12   0     -0.095" rgba="1 1 1 1"/>
                <geom size="0.005" pos="-0.09   0.039 -0.095" rgba="1 1 1 1"/>
                <geom size="0.005" pos="-0.09  -0.039 -0.095" rgba="1 1 1 1"/>
                <geom size="0.005" pos="0.12    0.035 -0.095" rgba="1 1 1 1"/>
                <geom size="0.005" pos="0.12   -0.043 -0.095" rgba="1 1 1 1"/>
                <geom size="0.005" pos="0.15   -0.01  -0.095" rgba="1 1 1 1"/>

              </body>
            </body>
          </body>
        </body>
      </body>
      <body name="R_hip_yaw_link">
        <inertial pos="-0.00116447 -0.0404495 0" quat="0.707002 0.707002 -0.0121739 -0.0121739" mass="0.219202" diaginertia="0.000598763 0.000555362 0.000156982"/>
        <joint name="R_hip_yaw" pos="0 0 0" axis="0 0 -1" range="-0.7854 0.7854" actuatorfrcrange="-100 100"/>
        <geom type="mesh" contype="0" conaffinity="0" group="1" density="0" rgba="1 1 1 1" mesh="R_hip_yaw_link"/>
<!--        <geom type="mesh" rgba="1 1 1 1" mesh="R_hip_yaw_link"/>-->
        <body name="R_hip_roll_link" pos="-0.0095 -0.12 0">
          <inertial pos="-0.0324725 0.00017925 -0.0726484" quat="0.655395 -0.252501 -0.247695 0.667344" mass="2.667" diaginertia="0.0108627 0.0094793 0.00603247"/>
          <joint name="R_hip_roll" pos="0 0 0" axis="-1 0 0" range="-0.524 0.524" actuatorfrcrange="-100 100"/>
          <geom type="mesh" contype="0" conaffinity="0" group="1" density="0" rgba="1 1 1 1" mesh="R_hip_roll_link"/>
          <geom type="mesh" rgba="1 1 1 1" mesh="R_hip_roll_link"/>
          <body name="R_hip_pitch_link" pos="0.0085 -0.001 -0.11">
            <inertial pos="0.00382921 0 -0.185485" quat="0.706557 0.0278188 0.0278169 0.706562" mass="1.664" diaginertia="0.0148443 0.0145077 0.0030868"/>
            <joint name="R_hip_pitch" pos="0 0 0" axis="0 -1 0" range="-2.4434 2.4434 " actuatorfrcrange="-100 100"/>
            <geom type="mesh" contype="0" conaffinity="0" group="1" density="0" rgba="1 1 1 1" mesh="R_hip_pitch_link"/>
            <geom type="mesh" rgba="1 1 1 1" mesh="R_hip_pitch_link"/>
            <body name="R_knee_pitch_link" pos="0 0 -0.35">
              <inertial pos="0.00140265 0 -0.15876" quat="0.706965 -0.0143148 -0.0143173 0.706958" mass="1.125" diaginertia="0.00999859 0.00987345 0.00100926"/>
              <joint name="R_knee_pitch" pos="0 0 0" axis="0 -1 0" range=" -2.3561 2.3561" actuatorfrcrange="-100 100"/>
              <geom type="mesh" contype="0" conaffinity="0" group="1" density="0" rgba="1 1 1 1" mesh="R_knee_pitch_link"/>
              <geom type="mesh" rgba="1 1 1 1" mesh="R_knee_pitch_link"/>
              <body name="R_ankle_pitch_link" pos="0 0 -0.35">
<!--                <inertial pos="0.0393998 0.00023708 -0.0784145" quat="-0.000325049 0.702196 -0.00149391 0.711983" mass="0.556161" diaginertia="0.00260529 0.00243297 0.000325398"/>-->
                <inertial pos="0.0393998 0.00023708 -0.0784145" quat="0 0.705556 0 0.708654" mass="0.556161" diaginertia="0.00260004 0.00215 0.000549961"/>
                <joint name="R_ankle_pitch" pos="0 0 0" axis="0 -1 0" range="-1.2217 1.2217" actuatorfrcrange="-50 50"/>
                <geom type="mesh" contype="0" conaffinity="0" group="1" density="0" rgba="1 1 1 1" mesh="R_ankle_pitch_link" euler="0 0.07 0"/>
                <geom size="0.005" pos="-0.12   0     -0.095" rgba="1 1 1 1"/>
                <geom size="0.005" pos="-0.09   0.039 -0.095" rgba="1 1 1 1"/>
                <geom size="0.005" pos="-0.09  -0.039 -0.095" rgba="1 1 1 1"/>
                <geom size="0.005" pos="0.12   -0.035 -0.095" rgba="1 1 1 1"/>
                <geom size="0.005" pos="0.12    0.043 -0.095" rgba="1 1 1 1"/>
                <geom size="0.005" pos="0.15    0.01  -0.095" rgba="1 1 1 1"/>
              </body>
            </body>
          </body>
        </body>
      </body>

      <body name="L_shoulder_pitch_link" pos="-0.01 0.14477 0.43584" quat="0.996195 0.0871543 0 0">
        <inertial pos="0 0.0287048 6.45e-05" quat="0.000604104 0.707107 0.000604104 0.707107" mass="0.08" diaginertia="9.30701e-05 6.96599e-05 4.183e-05"/>
        <joint name="L_shoulder_pitch" pos="0 0 0" axis="0 -1 0" range="-2 2" actuatorfrcrange="-30 30"/>
        <geom type="mesh" contype="0" conaffinity="0" group="1" density="0" rgba="1 1 1 1" mesh="L_shoulder_pitch_link"/>
        <geom type="mesh" rgba="1 1 1 1" mesh="L_shoulder_pitch_link"/>
        <body name="L_shoulder_roll_link" pos="0 0.061 0">
          <inertial pos="-0.00014962 0.00021332 -0.0425362" quat="0.707314 -0.000506345 0.00377108 0.706889" mass="0.8" diaginertia="0.000555526 0.000535819 0.000122295"/>
          <joint name="L_shoulder_roll" pos="0 0 0" axis="1 0 0" range="-0.35 1.57" actuatorfrcrange="-30 30"/>
          <geom type="mesh" contype="0" conaffinity="0" group="1" density="0" rgba="1 1 1 1" mesh="L_shoulder_roll_link"/>
          <geom type="mesh" rgba="1 1 1 1" mesh="L_shoulder_roll_link"/>
          <body name="L_shoulder_yaw_link" pos="0 0 -0.112">
            <inertial pos="0.0049554 -0.00024132 -0.14234" quat="0.999356 0.00104793 0.0349421 -0.00803437" mass="0.5" diaginertia="0.000629602 0.000609218 9.69596e-05"/>
            <joint name="L_shoulder_yaw" pos="0 0 0" axis="0 0 1" range="-2.618 2.618" actuatorfrcrange="-30 30"/>
            <geom type="mesh" contype="0" conaffinity="0" group="1" density="0" rgba="1 1 1 1" mesh="L_shoulder_yaw_link"/>
            <geom type="mesh" rgba="1 1 1 1" mesh="L_shoulder_yaw_link"/>
            <body name="L_elbow_pitch_link" pos="0.01 0 -0.173" quat="0.707388 0 -0.706825 0">
              <inertial pos="-0.0123066 0 -0.21266" quat="0.999999 2.13412e-06 -0.0016842 1.23684e-06" mass="0.1" diaginertia="0.00033997 0.00033631 0.000018723"/>
              <joint name="L_elbow_pitch" pos="0 0 0" axis="0 -1 0" range="-2.5 2.5" actuatorfrcrange="-30 30"/>
              <geom type="mesh" contype="0" conaffinity="0" group="1" density="0" rgba="1 1 1 1" mesh="L_elbow_pitch_link"/>
              <geom type="mesh" rgba="1 1 1 1" mesh="L_elbow_pitch_link"/>
              <body name="L_hand_link" pos="-0.01 0 -0.275">
                  <inertial pos="0 0 0" mass="0.05" diaginertia="1e-5 1e-5 1e-5"/>
                  <geom type="sphere" size="0.04" rgba="1 0 1 1"/>
              </body>
            </body>
          </body>
        </body>
      </body>
      <body name="R_shoulder_pitch_link" pos="-0.01 -0.14477 0.43584" quat="0.996195 -0.0871543 0 0">
        <inertial pos="0 -0.0287048 6.45e-05" quat="-0.000604104 0.707107 -0.000604104 0.707107" mass="0.08" diaginertia="9.30701e-05 6.96599e-05 4.183e-05"/>
        <joint name="R_shoulder_pitch" pos="0 0 0" axis="0 -1 0" range="-2 2" actuatorfrcrange="-30 30"/>
        <geom type="mesh" contype="0" conaffinity="0" group="1" density="0" rgba="1 1 1 1" mesh="R_shoulder_pitch_link"/>
        <geom type="mesh" rgba="1 1 1 1" mesh="R_shoulder_pitch_link"/>
        <body name="R_shoulder_roll_link" pos="0 -0.061 0">
          <inertial pos="0.00014963 -0.00021332 -0.0425362" quat="0.707314 0.000506345 -0.00377108 0.706889" mass="0.8" diaginertia="0.000555526 0.000535819 0.000122295"/>
          <joint name="R_shoulder_roll" pos="0 0 0" axis="-1 0 0" range="-1.57 1.57" actuatorfrcrange="-30 30"/>
          <geom type="mesh" contype="0" conaffinity="0" group="1" density="0" rgba="1 1 1 1" mesh="R_shoulder_roll_link"/>
          <geom type="mesh" rgba="1 1 1 1" mesh="R_shoulder_roll_link"/>
          <body name="R_shoulder_yaw_link" pos="-3.8964e-05 0 -0.112">
            <inertial pos="0.0049944 -0.00024129 -0.142337" quat="0.999356 0.00104793 0.0349421 -0.00803437" mass="0.5" diaginertia="0.000629602 0.000609218 9.69596e-05"/>
            <joint name="R_shoulder_yaw" pos="0 0 0" axis="0 0 -1" range="-2.618 2.618" actuatorfrcrange="-30 30"/>
            <geom type="mesh" contype="0" conaffinity="0" group="1" density="0" rgba="1 1 1 1" mesh="R_shoulder_yaw_link"/>
            <geom type="mesh" rgba="1 1 1 1" mesh="R_shoulder_yaw_link"/>
            <body name="R_elbow_pitch_link" pos="0.010039 0 -0.173" quat="0.707388 0 -0.706825 0">
              <inertial pos="-0.0123066 0 -0.21266" quat="0.999999 2.13412e-06 -0.0016842 1.23684e-06" mass="0.1" diaginertia="0.00033997 0.00033631 0.000018723"/>
              <joint name="R_elbow_pitch" pos="0 0 0" axis="0 -1 0" range="-2.5 2.5" actuatorfrcrange="-30 30"/>
              <geom type="mesh" contype="0" conaffinity="0" group="1" density="0" rgba="1 1 1 1" mesh="R_elbow_pitch_link"/>
              <geom type="mesh" rgba="1 1 1 1" mesh="R_elbow_pitch_link"/>
              <body name="R_hand_link" pos="-0.01 0 -0.275">
                  <inertial pos="0 0 0" mass="0.05" diaginertia="1e-5 1e-5 1e-5"/>
                  <geom type="sphere" size="0.04" rgba="1 0 1 1"/>
              </body>
            </body>
          </body>
        </body>
      </body>
    </body>
  </worldbody>


  <actuator>
    <motor name="L_hip_yaw" joint="L_hip_yaw"/>
    <motor name="L_hip_roll" joint="L_hip_roll"/>
    <motor name="L_hip_pitch" joint="L_hip_pitch"/>
    <motor name="L_knee_pitch" joint="L_knee_pitch"/>
    <motor name="L_ankle_pitch" joint="L_ankle_pitch"/>
    <motor name="R_hip_yaw" joint="R_hip_yaw"/>
    <motor name="R_hip_roll" joint="R_hip_roll"/>
    <motor name="R_hip_pitch" joint="R_hip_pitch"/>
    <motor name="R_knee_pitch" joint="R_knee_pitch"/>
    <motor name="R_ankle_pitch" joint="R_ankle_pitch"/>
    <motor name="L_shoulder_pitch" joint="L_shoulder_pitch"/>
    <motor name="L_shoulder_roll" joint="L_shoulder_roll"/>
    <motor name="L_shoulder_yaw" joint="L_shoulder_yaw"/>
    <motor name="L_elbow_pitch" joint="L_elbow_pitch"/>
    <motor name="R_shoulder_pitch" joint="R_shoulder_pitch"/>
    <motor name="R_shoulder_roll" joint="R_shoulder_roll"/>
    <motor name="R_shoulder_yaw" joint="R_shoulder_yaw"/>
    <motor name="R_elbow_pitch" joint="R_elbow_pitch"/>
  </actuator>
  <sensor>

        <framequat name="BodyQuat" objtype="site" objname="imu"/>
  </sensor>
</mujoco>

